x=45
try:
    print(x)
except:
    print("An exception occured")
finally:
    print("Try and accept is over")




try:
    print(y)
except:
    print("An exception occured")
finally:
    print("Try and accept is over")



